[0m20:07:40.069091 [debug] [MainThread]: Sending event: {'category': 'dbt', 'action': 'invocation', 'label': 'start', 'context': [<snowplow_tracker.self_describing_json.SelfDescribingJson object at 0x000001A170F4C980>, <snowplow_tracker.self_describing_json.SelfDescribingJson object at 0x000001A1739839E0>, <snowplow_tracker.self_describing_json.SelfDescribingJson object at 0x000001A173983860>]}


============================== 20:07:40.073607 | 20a38f56-369c-4708-88eb-c7e8783d889b ==============================
[0m20:07:40.073607 [info ] [MainThread]: Running with dbt=1.9.4
[0m20:07:40.075129 [debug] [MainThread]: running dbt with arguments {'printer_width': '80', 'indirect_selection': 'eager', 'write_json': 'True', 'log_cache_events': 'False', 'partial_parse': 'True', 'cache_selected_only': 'False', 'profiles_dir': 'C:\\Users\\prado\\.dbt', 'debug': 'False', 'version_check': 'True', 'log_path': 'logs', 'fail_fast': 'False', 'warn_error': 'None', 'use_colors': 'True', 'use_experimental_parser': 'False', 'empty': 'None', 'quiet': 'False', 'no_print': 'None', 'log_format': 'default', 'invocation_command': 'dbt init', 'static_parser': 'True', 'introspect': 'True', 'target_path': 'None', 'warn_error_options': 'WarnErrorOptions(include=[], exclude=[])', 'send_anonymous_usage_stats': 'True'}
[0m20:12:10.247851 [debug] [MainThread]: Starter project path: C:\Users\prado\projetos\analytics_engineering_curse\dbt\Lib\site-packages\dbt\include\starter_project
[0m20:12:10.262443 [info ] [MainThread]: 
Your new dbt project "tesouro" was created!

For more information on how to configure the profiles.yml file,
please consult the dbt documentation here:

  https://docs.getdbt.com/docs/configure-your-profile

One more thing:

Need help? Don't hesitate to reach out to us via GitHub issues or on Slack:

  https://community.getdbt.com/

Happy modeling!

[0m20:12:10.262443 [info ] [MainThread]: Setting up your profile.
[0m20:12:12.091679 [info ] [MainThread]: Profile tesouro written to C:\Users\prado\.dbt\profiles.yml using target's sample configuration. Once updated, you'll be able to start developing with dbt.
[0m20:12:12.093677 [debug] [MainThread]: Command `dbt init` succeeded at 20:12:12.093677 after 272.13 seconds
[0m20:12:12.093677 [debug] [MainThread]: Sending event: {'category': 'dbt', 'action': 'invocation', 'label': 'end', 'context': [<snowplow_tracker.self_describing_json.SelfDescribingJson object at 0x000001A1737C0CE0>, <snowplow_tracker.self_describing_json.SelfDescribingJson object at 0x000001A16E4E80E0>, <snowplow_tracker.self_describing_json.SelfDescribingJson object at 0x000001A173122570>]}
[0m20:12:12.094680 [debug] [MainThread]: Flushing usage events
[0m20:12:12.685830 [debug] [MainThread]: An error was encountered while trying to flush usage events
[0m20:12:57.577778 [debug] [MainThread]: Sending event: {'category': 'dbt', 'action': 'invocation', 'label': 'start', 'context': [<snowplow_tracker.self_describing_json.SelfDescribingJson object at 0x0000029E88585730>, <snowplow_tracker.self_describing_json.SelfDescribingJson object at 0x0000029E8CAA61B0>, <snowplow_tracker.self_describing_json.SelfDescribingJson object at 0x0000029E8CF54170>]}


============================== 20:12:57.580785 | af1c4e08-b6fd-487e-915c-633840e63c0f ==============================
[0m20:12:57.580785 [info ] [MainThread]: Running with dbt=1.9.4
[0m20:12:57.581785 [debug] [MainThread]: running dbt with arguments {'printer_width': '80', 'indirect_selection': 'eager', 'write_json': 'True', 'log_cache_events': 'False', 'partial_parse': 'True', 'cache_selected_only': 'False', 'profiles_dir': 'C:\\Users\\prado\\.dbt', 'fail_fast': 'False', 'warn_error': 'None', 'log_path': 'logs', 'debug': 'False', 'version_check': 'True', 'use_colors': 'True', 'use_experimental_parser': 'False', 'empty': 'None', 'quiet': 'False', 'no_print': 'None', 'log_format': 'default', 'invocation_command': 'dbt init', 'introspect': 'True', 'warn_error_options': 'WarnErrorOptions(include=[], exclude=[])', 'target_path': 'None', 'static_parser': 'True', 'send_anonymous_usage_stats': 'True'}
[0m20:13:02.301450 [error] [MainThread]: Encountered an error:

[0m20:13:02.303954 [error] [MainThread]: Traceback (most recent call last):
  File "C:\Users\prado\projetos\analytics_engineering_curse\dbt\Lib\site-packages\dbt\cli\requires.py", line 153, in wrapper
    result, success = func(*args, **kwargs)
                      ^^^^^^^^^^^^^^^^^^^^^
  File "C:\Users\prado\projetos\analytics_engineering_curse\dbt\Lib\site-packages\dbt\cli\requires.py", line 103, in wrapper
    return func(*args, **kwargs)
           ^^^^^^^^^^^^^^^^^^^^^
  File "C:\Users\prado\projetos\analytics_engineering_curse\dbt\Lib\site-packages\dbt\cli\main.py", line 477, in init
    results = task.run()
              ^^^^^^^^^^
  File "C:\Users\prado\projetos\analytics_engineering_curse\dbt\Lib\site-packages\dbt\task\init.py", line 324, in run
    project_name = self.get_valid_project_name()
                   ^^^^^^^^^^^^^^^^^^^^^^^^^^^^^
  File "C:\Users\prado\projetos\analytics_engineering_curse\dbt\Lib\site-packages\dbt\task\init.py", line 278, in get_valid_project_name
    name = click.prompt("Enter a name for your project (letters, digits, underscore)")
           ^^^^^^^^^^^^^^^^^^^^^^^^^^^^^^^^^^^^^^^^^^^^^^^^^^^^^^^^^^^^^^^^^^^^^^^^^^^
  File "C:\Users\prado\projetos\analytics_engineering_curse\dbt\Lib\site-packages\click\termui.py", line 164, in prompt
    value = prompt_func(prompt)
            ^^^^^^^^^^^^^^^^^^^
  File "C:\Users\prado\projetos\analytics_engineering_curse\dbt\Lib\site-packages\click\termui.py", line 147, in prompt_func
    raise Abort() from None
click.exceptions.Abort

[0m20:13:02.304964 [debug] [MainThread]: Command `dbt init` failed at 20:13:02.304964 after 4.84 seconds
[0m20:13:02.304964 [debug] [MainThread]: Sending event: {'category': 'dbt', 'action': 'invocation', 'label': 'end', 'context': [<snowplow_tracker.self_describing_json.SelfDescribingJson object at 0x0000029E8AC7AB40>, <snowplow_tracker.self_describing_json.SelfDescribingJson object at 0x0000029E8E282F90>, <snowplow_tracker.self_describing_json.SelfDescribingJson object at 0x0000029E8CF03B60>]}
[0m20:13:02.305979 [debug] [MainThread]: Flushing usage events
[0m20:13:02.783538 [debug] [MainThread]: An error was encountered while trying to flush usage events
[0m20:13:11.741295 [debug] [MainThread]: Sending event: {'category': 'dbt', 'action': 'invocation', 'label': 'start', 'context': [<snowplow_tracker.self_describing_json.SelfDescribingJson object at 0x000001FC05D3AF30>, <snowplow_tracker.self_describing_json.SelfDescribingJson object at 0x000001FC03822A80>, <snowplow_tracker.self_describing_json.SelfDescribingJson object at 0x000001FC03246600>]}


============================== 20:13:11.745916 | 47d18237-0805-4921-82d3-9f538a8371fc ==============================
[0m20:13:11.745916 [info ] [MainThread]: Running with dbt=1.9.4
[0m20:13:11.745916 [debug] [MainThread]: running dbt with arguments {'printer_width': '80', 'indirect_selection': 'eager', 'log_cache_events': 'False', 'write_json': 'True', 'partial_parse': 'True', 'cache_selected_only': 'False', 'profiles_dir': 'C:\\Users\\prado\\.dbt', 'debug': 'False', 'fail_fast': 'False', 'log_path': 'logs', 'warn_error': 'None', 'version_check': 'True', 'use_colors': 'True', 'use_experimental_parser': 'False', 'empty': 'False', 'quiet': 'False', 'no_print': 'None', 'warn_error_options': 'WarnErrorOptions(include=[], exclude=[])', 'introspect': 'True', 'invocation_command': 'dbt run', 'static_parser': 'True', 'target_path': 'None', 'log_format': 'default', 'send_anonymous_usage_stats': 'True'}
[0m20:13:11.747037 [error] [MainThread]: Encountered an error:
Runtime Error
  No dbt_project.yml found at expected path C:\Users\prado\projetos\analytics_engineering_curse\dbt_project.yml
  Verify that each entry within packages.yml (and their transitive dependencies) contains a file named dbt_project.yml
  
[0m20:13:11.748395 [debug] [MainThread]: Command `dbt run` failed at 20:13:11.748395 after 0.11 seconds
[0m20:13:11.748395 [debug] [MainThread]: Sending event: {'category': 'dbt', 'action': 'invocation', 'label': 'end', 'context': [<snowplow_tracker.self_describing_json.SelfDescribingJson object at 0x000001FC05D3A270>, <snowplow_tracker.self_describing_json.SelfDescribingJson object at 0x000001FC071C55B0>, <snowplow_tracker.self_describing_json.SelfDescribingJson object at 0x000001FC071A15E0>]}
[0m20:13:11.749407 [debug] [MainThread]: Flushing usage events
[0m20:13:12.234921 [debug] [MainThread]: An error was encountered while trying to flush usage events
[0m19:26:15.627745 [debug] [MainThread]: Sending event: {'category': 'dbt', 'action': 'invocation', 'label': 'start', 'context': [<snowplow_tracker.self_describing_json.SelfDescribingJson object at 0x0000026243B4B2F0>, <snowplow_tracker.self_describing_json.SelfDescribingJson object at 0x0000026243B4A090>, <snowplow_tracker.self_describing_json.SelfDescribingJson object at 0x0000026243B48200>]}


============================== 19:26:15.646361 | 331d641b-6824-477f-8015-57a0d95dc63d ==============================
[0m19:26:15.646361 [info ] [MainThread]: Running with dbt=1.9.4
[0m19:26:15.647360 [debug] [MainThread]: running dbt with arguments {'printer_width': '80', 'indirect_selection': 'eager', 'log_cache_events': 'False', 'write_json': 'True', 'partial_parse': 'True', 'cache_selected_only': 'False', 'warn_error': 'None', 'fail_fast': 'False', 'debug': 'False', 'log_path': 'logs', 'version_check': 'True', 'profiles_dir': 'C:\\Users\\prado\\.dbt', 'use_colors': 'True', 'use_experimental_parser': 'False', 'no_print': 'None', 'quiet': 'False', 'empty': 'None', 'warn_error_options': 'WarnErrorOptions(include=[], exclude=[])', 'introspect': 'True', 'static_parser': 'True', 'invocation_command': 'dbt seed', 'target_path': 'None', 'log_format': 'default', 'send_anonymous_usage_stats': 'True'}
[0m19:26:15.648363 [error] [MainThread]: Encountered an error:
Runtime Error
  No dbt_project.yml found at expected path C:\Users\prado\projetos\analytics_engineering_curse\dbt_project.yml
  Verify that each entry within packages.yml (and their transitive dependencies) contains a file named dbt_project.yml
  
[0m19:26:15.649353 [debug] [MainThread]: Command `dbt seed` failed at 19:26:15.649353 after 0.13 seconds
[0m19:26:15.649353 [debug] [MainThread]: Sending event: {'category': 'dbt', 'action': 'invocation', 'label': 'end', 'context': [<snowplow_tracker.self_describing_json.SelfDescribingJson object at 0x0000026243D45E80>, <snowplow_tracker.self_describing_json.SelfDescribingJson object at 0x00000262437D5F40>, <snowplow_tracker.self_describing_json.SelfDescribingJson object at 0x00000262437D5700>]}
[0m19:26:15.649353 [debug] [MainThread]: Flushing usage events
[0m19:26:16.271471 [debug] [MainThread]: An error was encountered while trying to flush usage events
[0m18:52:22.141990 [debug] [MainThread]: Sending event: {'category': 'dbt', 'action': 'invocation', 'label': 'start', 'context': [<snowplow_tracker.self_describing_json.SelfDescribingJson object at 0x000002F084EB3380>, <snowplow_tracker.self_describing_json.SelfDescribingJson object at 0x000002F0875B8B00>, <snowplow_tracker.self_describing_json.SelfDescribingJson object at 0x000002F087243BC0>]}


============================== 18:52:22.160606 | b5396a9d-1357-454b-be9b-128068a2943e ==============================
[0m18:52:22.160606 [info ] [MainThread]: Running with dbt=1.9.4
[0m18:52:22.160606 [debug] [MainThread]: running dbt with arguments {'printer_width': '80', 'indirect_selection': 'eager', 'write_json': 'True', 'log_cache_events': 'False', 'partial_parse': 'True', 'cache_selected_only': 'False', 'profiles_dir': 'C:\\Users\\prado\\.dbt', 'version_check': 'True', 'debug': 'False', 'log_path': 'logs', 'warn_error': 'None', 'fail_fast': 'False', 'use_colors': 'True', 'use_experimental_parser': 'False', 'no_print': 'None', 'quiet': 'False', 'empty': 'False', 'warn_error_options': 'WarnErrorOptions(include=[], exclude=[])', 'introspect': 'True', 'invocation_command': 'dbt run', 'static_parser': 'True', 'target_path': 'None', 'log_format': 'default', 'send_anonymous_usage_stats': 'True'}
[0m18:52:22.160606 [error] [MainThread]: Encountered an error:
Runtime Error
  No dbt_project.yml found at expected path C:\Users\prado\projetos\analytics_engineering_curse\dbt_project.yml
  Verify that each entry within packages.yml (and their transitive dependencies) contains a file named dbt_project.yml
  
[0m18:52:22.162626 [debug] [MainThread]: Command `dbt run` failed at 18:52:22.162626 after 0.13 seconds
[0m18:52:22.162626 [debug] [MainThread]: Sending event: {'category': 'dbt', 'action': 'invocation', 'label': 'end', 'context': [<snowplow_tracker.self_describing_json.SelfDescribingJson object at 0x000002F0875396A0>, <snowplow_tracker.self_describing_json.SelfDescribingJson object at 0x000002F084E7BBF0>, <snowplow_tracker.self_describing_json.SelfDescribingJson object at 0x000002F0875068D0>]}
[0m18:52:22.162626 [debug] [MainThread]: Flushing usage events
[0m18:52:22.837611 [debug] [MainThread]: An error was encountered while trying to flush usage events
[0m19:17:56.189113 [debug] [MainThread]: Sending event: {'category': 'dbt', 'action': 'invocation', 'label': 'start', 'context': [<snowplow_tracker.self_describing_json.SelfDescribingJson object at 0x0000022952F38140>, <snowplow_tracker.self_describing_json.SelfDescribingJson object at 0x0000022952917590>, <snowplow_tracker.self_describing_json.SelfDescribingJson object at 0x0000022952917530>]}


============================== 19:17:56.192633 | 3bae60ae-e0c2-42a6-a7b0-37470e0e5f98 ==============================
[0m19:17:56.192633 [info ] [MainThread]: Running with dbt=1.9.4
[0m19:17:56.193642 [debug] [MainThread]: running dbt with arguments {'printer_width': '80', 'indirect_selection': 'eager', 'log_cache_events': 'False', 'write_json': 'True', 'partial_parse': 'True', 'cache_selected_only': 'False', 'warn_error': 'None', 'debug': 'False', 'profiles_dir': 'C:\\Users\\prado\\.dbt', 'log_path': 'logs', 'fail_fast': 'False', 'version_check': 'True', 'use_colors': 'True', 'use_experimental_parser': 'False', 'empty': 'None', 'quiet': 'False', 'no_print': 'None', 'warn_error_options': 'WarnErrorOptions(include=[], exclude=[])', 'introspect': 'True', 'log_format': 'default', 'static_parser': 'True', 'target_path': 'None', 'invocation_command': 'dbt docs serve', 'send_anonymous_usage_stats': 'True'}
[0m19:17:56.194263 [error] [MainThread]: Encountered an error:
Runtime Error
  No dbt_project.yml found at expected path C:\Users\prado\projetos\analytics_engineering_curse\dbt_project.yml
  Verify that each entry within packages.yml (and their transitive dependencies) contains a file named dbt_project.yml
  
[0m19:17:56.195269 [debug] [MainThread]: Command `dbt docs serve` failed at 19:17:56.195269 after 0.17 seconds
[0m19:17:56.195269 [debug] [MainThread]: Sending event: {'category': 'dbt', 'action': 'invocation', 'label': 'end', 'context': [<snowplow_tracker.self_describing_json.SelfDescribingJson object at 0x0000022954136030>, <snowplow_tracker.self_describing_json.SelfDescribingJson object at 0x00000229540663C0>, <snowplow_tracker.self_describing_json.SelfDescribingJson object at 0x00000229528B14C0>]}
[0m19:17:56.195269 [debug] [MainThread]: Flushing usage events
[0m19:17:56.711431 [debug] [MainThread]: An error was encountered while trying to flush usage events
